Workbook

Sheet Start here
B2: Amount review — checking our largest records against the source
B3: Built 24 September 2026 from the database as loaded 2026-08-31. 213 records: 65 suspects (A), 135 large (B), 13 institution top-fives (C).
B5: What this is for
B6: Our two biggest amount errors so far (IDB Invest's group figure, AfDB's programme envelope) were found by accident. This queue checks the records that carry the most dollars, so the next one is found on purpose. The 200 largest records alone are about an eighth of every dollar in the tracker.
B7: Each check takes one to three minutes. At five a day, priority A takes about 13 days and the whole queue about 43. Priority A is where the errors should be; the rest is confirmation.
B9: Step by step
B10: 1. Open the 'Queue' tab. Work top to bottom: it is already sorted, suspects first, then by size.
B11: 2. Find the first row with an empty yellow 'Verdict' cell.
B12: 3. Read the grey cells: who, what, OUR amount in the source's own currency, and the 'Already known' note if there is one.
B13: 4. Click the link in 'Source' ('Open page', or a web search for EBRD and some Proparco records). Use the 'Institution guide' tab to find where that institution puts the amount, and which differences are normal for it.
B14: 5. Find the institution's OWN commitment for this deal. Not the total project cost, not a programme or facility total, not co-financiers' money.
B15: 6. Fill the yellow cells: pick a Verdict from the dropdown; type the amount the page shows, in the page's currency, as a plain number (250000000, not '250m'); the currency; the words the page uses for it; and today's date (Ctrl+; types it).
... B37: The 'Progress' tab counts what you've done.

Sheet Queue
A1: # | B1: Review ID | C1: Priority | D1: Why it's here | E1: Institution | F1: Project name | G1: Country | H1: Year | I1: Our amount (source currency) | J1: Currency | K1: Our amount (USD m) | L1: Rank within institution | M1: Already known | N1: Source | O1: Verdict | P1: Amount on page | Q1: Page currency | R1: What the page calls it | S1: Notes | T1: Date reviewed | U1: Source URL (key) | V1: Approval date (key) | W1: Exact name (key)
A2: 1 | B2: AR-001 | C2: A | D2: trade-finance line; IFC 'World Region' record of USD 500m or more | E2: IFC | F2: Global Trade Finance Program (GTFP) | G2: Regional — Global | H2: 2004 | I2: 7000000000 | J2: USD | K2: 7000 | L2: 1 | M2: IFC's trade programmes stamp their whole envelope on partner records. Since 24 Sep 2026 the loader blanks it wherever several World Region records share one (GSCF, GTSF), but a LONE World Region record keeps its amount as the programme's own. Check whether this is the programme itself or one partner bank. Trade lines revolve: check whether the figure is a LIMIT (one commitment) or a running total of trade covered over the years. | N2: =HYPERLINK("https://disclosures.ifc.org/project-detail/SPI/23898/global-trade-finance-program-(gtfp)","Open page") | U2: https://disclosures.ifc.org/project-detail/SPI/23898/global-trade-finance-program-(gtfp) | V2: 2004-11-11 | W2: Global Trade Finance Program (GTFP)
A3: 2 | B3: AR-002 | C3: A | D3: trade-finance line | E3: EBRD | F3: Regional TFP: National Bank Of Egypt | G3: Egypt | H3: 2014 | I3: 3.4158555e+09 | J3: EUR | K3: 4537.9674 | L3: 1 | M3: Trade lines revolve: check whether the figure is a LIMIT (one commitment) or a running total of trade covered over the years. Our figure is EBRD's 'Net Cumulative Bank Investment'. | N3: =HYPERLINK("https://www.google.com/search?q=site%3Aebrd.com%2Fhome%2Fwork-with-us%2Fprojects%2Fpsd+Regional+TFP%3A+National+Bank+Of+Egypt","Search EBRD") | U3: https://www.ebrd.com/content/dam/ebrd_dxp/assets/pdfs/publications/ebrd-investments-1991-2025.xlsx | V3: 2014-02-19 | W3: Regional TFP: National Bank Of Egypt
A4: 3 | B4: AR-003 | C4: A | D4: trade-finance line | E4: EBRD | F4: Regional TFP: AikBank | G4: Serbia | H4: 2011 | I4: 1.8260238e+09 | J4: EUR | K4: 2541.7429 | L4: 2 | M4: Trade lines revolve: check whether the figure is a LIMIT (one commitment) or a running total of trade covered over the years. Our figure is EBRD's 'Net Cumulative Bank Investment'. | N4: =HYPERLINK("https://www.google.com/search?q=site%3Aebrd.com%2Fhome%2Fwork-with-us%2Fprojects%2Fpsd+Regional+TFP%3A+AikBank","Search EBRD") | U4: https://www.ebrd.com/content/dam/ebrd_dxp/assets/pdfs/publications/ebrd-investments-1991-2025.xlsx | V4: 2011-02-14 | W4: Regional TFP: AikBank
A5: 4 | B5: AR-004 | C5: A | D5: trade-finance line | E5: EBRD | F5: Regional TFP: BMCE Banque Marocaine pour le Commerce Exterie | G5: Morocco | H5: 2013 | I5: 1.555993e+09 | J5: EUR | K5: 2066.5423 | L5: 3 | M5: Trade lines revolve: check whether the figure is a LIMIT (one commitment) or a running total of trade covered over the years. Our figure is EBRD's 'Net Cumulative Bank Investment'. | N5: =HYPERLINK("https://www.google.com/search?q=site%3Aebrd.com%2Fhome%2Fwork-with-us%2Fprojects%2Fpsd+Regional+TFP%3A+BMCE+Banque+Marocaine+pour+le+Commerce+Exterie","Search EBRD") | U5: https://www.ebrd.com/content/dam/ebrd_dxp/assets/pdfs/publications/ebrd-investments-1991-2025.xlsx | V5: 2013-03-07 | W5: Regional TFP: BMCE Banque Marocaine pour le Commerce Exterie
A6: 5 | B6: AR-005 | C6: A | D6: trade-finance line | E6: EBRD | F6: Regional TFP: Export Import Bank of Ukraine (UkrExIm) | G6: Ukraine | H6: 2007 | I6: 1.5069439e+09 | J6: EUR | K6: 2065.2335 | L6: 4 | M6: Trade lines revolve: check whether the figure is a LIMIT (one commitment) or a running total of trade covered over the years. Our figure is EBRD's 'Net Cumulative Bank Investment'. | N6: =HYPERLINK("https://www.google.com/search?q=site%3Aebrd.com%2Fhome%2Fwork-with-us%2Fprojects%2Fpsd+Regional+TFP%3A+Export+Import+Bank+of+Ukraine+%28UkrExIm%29","Search EBRD") | U6: https://www.ebrd.com/content/dam/ebrd_dxp/assets/pdfs/publications/ebrd-investments-1991-2025.xlsx | V6: 2007-05-20 | W6: Regional TFP: Export Import Bank of Ukraine (UkrExIm)
A7: 6 | B7: AR-006 | C7: A | D7: trade-finance line | E7: EBRD | F7: Regional TFP: Banque Misr | G7: Egypt | H7: 2018 | I7: 1.488434e+09 | J7: EUR | K7: 1757.7736 | L7: 5 | M7: Trade lines revolve: check whether the figure is a LIMIT (one commitment) or a running total of trade covered over the years. Our figure is EBRD's 'Net Cumulative Bank Investment'. | N7: =HYPERLINK("https://www.google.com/search?q=site%3Aebrd.com%2Fhome%2Fwork-with-us%2Fprojects%2Fpsd+Regional+TFP%3A+Banque+Misr","Search EBRD") | U7: https://www.ebrd.com/content/dam/ebrd_dxp/assets/pdfs/publications/ebrd-investments-1991-2025.xlsx | V7: 2018-09-26 | W7: Regional TFP: Banque Misr
A8: 7 | B8: AR-007 | C8: A | D8: trade-finance line | E8: IDB Invest | F8: Banco de Reservas - TFFP | G8: Dominican Republic | H8: 2009 | I8: 1605000000 | J8: USD | K8: 1605 | L8: 1 | M8: Trade lines revolve: check whether the figure is a LIMIT (one commitment) or a running total of trade covered over the years. | N8: =HYPERLINK("https://idbinvest.org/en/projects/banco-de-reservas-tffp","Open page") | U8: https://idbinvest.org/en/projects/banco-de-reservas-tffp | V8: 2009-03-24 | W8: Banco de Reservas - TFFP
A9: 8 | B9: AR-008 | C9: A | D9: trade-finance line | E9: EBRD | F9: Regional TFP: Promsvyazbank | G9: Russia | H9: 2004 | I9: 1.2389867e+09 | J9: EUR | K9: 1541.178 | L9: 6 | M9: Trade lines revolve: check whether the figure is a LIMIT (one commitment) or a running total of trade covered over the years. Our figure is EBRD's 'Net Cumulative Bank Investment'. | N9: =HYPERLINK("https://www.google.com/search?q=site%3Aebrd.com%2Fhome%2Fwork-with-us%2Fprojects%2Fpsd+Regional+TFP%3A+Promsvyazbank","Search EBRD") | U9: https://www.ebrd.com/content/dam/ebrd_dxp/assets/pdfs/publications/ebrd-investments-1991-2025.xlsx | V9: 2004-11-12 | W9: Regional TFP: Promsvyazbank
A10: 9 | B10: AR-009 | C10: A | D10: trade-finance line; IFC 'World Region' record of USD 500m or more | E10: IFC | F10: GTFP IV | G10: Regional — Global | H10: 2008 | I10: 1500000000 | J10: USD | K10: 1500 | L10: 2 | M10: IFC's trade programmes stamp their whole envelope on partner records. Since 24 Sep 2026 the loader blanks it wherever several World Region records share one (GSCF, GTSF), but a LONE World Region record keeps its amount as the programme's own. Check whether this is the programme itself or one partner bank. Trade lines revolve: check whether the figure is a LIMIT (one commitment) or a running total of trade covered over the years. | N10: =HYPERLINK("https://disclosures.ifc.org/project-detail/SPI/27839/gtfp-iv","Open page") | U10: https://disclosures.ifc.org/project-detail/SPI/27839/gtfp-iv | V10: 2008-12-18 | W10: GTFP IV
A11: 10 | B11: AR-010 | C11: A | D11: trade-finance line | E11: EBRD | F11: Regional TFP: Ukrgasbank | G11: Ukraine | H11: 2019 | I11: 1.2800839e+09 | J11: EUR | K11: 1433.022 | L11: 7 | M11: Trade lines revolve: check whether the figure is a LIMIT (one commitment) or a running total of trade covered over the years. Our figure is EBRD's 'Net Cumulative Bank Investment'. | N11: =HYPERLINK("https://www.google.com/search?q=site%3Aebrd.com%2Fhome%2Fwork-with-us%2Fprojects%2Fpsd+Regional+TFP%3A+Ukrgasbank","Search EBRD") | U11: https://www.ebrd.com/content/dam/ebrd_dxp/assets/pdfs/publications/ebrd-investments-1991-2025.xlsx | V11: 2019-07-04 | W11: Regional TFP: Ukrgasbank
A12: 11 | B12: AR-011 | C12: A | D12: trade-finance line | E12: EBRD | F12: Regional TFP: Raiffeisen Bank Ukraine | G12: Ukraine | H12: 2003 | I12: 1.1718922e+09 | J12: EUR | K12: 1325.5976 | L12: 8 | M12: Trade lines revolve: check whether the figure is a LIMIT (one commitment) or a running total of trade covered over the years. Our figure is EBRD's 'Net Cumulative Bank Investment'. | N12: =HYPERLINK("https://www.google.com/search?q=site%3Aebrd.com%2Fhome%2Fwork-with-us%2Fprojects%2Fpsd+Regional+TFP%3A+Raiffeisen+Bank+Ukraine","Search EBRD") | U12: https://www.ebrd.com/content/dam/ebrd_dxp/assets/pdfs/publications/ebrd-investments-1991-2025.xlsx | V12: 2003-05-27 | W12: Regional TFP: Raiffeisen Bank Ukraine
A13: 12 | B13: AR-012 | C13: A | D13: trade-finance line | E13: EBRD | F13: Regional TFP: National Bank of Greece | G13: Greece | H13: 2016 | I13: 9.6995795e+08 | J13: EUR | K13: 1073.6494 | L13: 9 | M13: Trade lines revolve: check whether the figure is a LIMIT (one commitment) or a running total of trade covered over the years. Our figure is EBRD's 'Net Cumulative Bank Investment'. | N13: =HYPERLINK("https://www.google.com/search?q=site%3Aebrd.com%2Fhome%2Fwork-with-us%2Fprojects%2Fpsd+Regional+TFP%3A+National+Bank+of+Greece","Search EBRD") | U13: https://www.ebrd.com/content/dam/ebrd_dxp/assets/pdfs/publications/ebrd-investments-1991-2025.xlsx | V13: 2016-03-01 | W13: Regional TFP: National Bank of Greece
A14: 13 | B14: AR-013 | C14: A | D14: trade-finance line | E14: EBRD | F14: Regional TFP: TBC Bank (guarantee & pre-export) | G14: Georgia | H14: 1999 | I14: 9.8311367e+08 | J14: EUR | K14: 1047.779 | L14: 10 | M14: Trade lines revolve: check whether the figure is a LIMIT (one commitment) or a running total of trade covered over the years. Our figure is EBRD's 'Net Cumulative Bank Investment'. | N14: =HYPERLINK("https://www.google.com/search?q=site%3Aebrd.com%2Fhome%2Fwork-with-us%2Fprojects%2Fpsd+Regional+TFP%3A+TBC+Bank+%28guarantee+%26+pre-export%29","Search EBRD") | U14: https://www.ebrd.com/content/dam/ebrd_dxp/assets/pdfs/publications/ebrd-investments-1991-2025.xlsx | V14: 1999-08-17 | W14: Regional TFP: TBC Bank (guarantee & pre-export)
A15: 14 | B15: AR-014 | C15: A | D15: IFC 'World Region' record of USD 500m or more | E15: IFC | F15: Bank Recap Fund | G15: Regional — Global | H15: 2008 | I15: 1003000000 | J15: USD | K15: 1003 | L15: 3 | M15: IFC's trade programmes stamp their whole envelope on partner records. Since 24 Sep 2026 the loader blanks it wherever several World Region records share one (GSCF, GTSF), but a LONE World Region record keeps its amount as the programme's own. Check whether this is the programme itself or one partner bank. | N15: =HYPERLINK("https://disclosures.ifc.org/project-detail/SPI/27832/bank-recap-fund","Open page") | U15: https://disclosures.ifc.org/project-detail/SPI/27832/bank-recap-fund | V15: 2008-12-18 | W15: Bank Recap Fund
A16: 15 | B16: AR-015 | C16: A | D16: trade-finance line | E16: ADB | F16: REG: TRADE FINANCE FACILITATION PROGRAM | G16: Regional — Asia | H16: 2009 | I16: 1000000000 | J16: USD | K16: 1000 | L16: 1 | M16: Trade lines revolve: check whether the figure is a LIMIT (one commitment) or a running total of trade covered over the years. | N16: =HYPERLINK("https://www.adb.org/projects/37909-024/main","Open page") | U16: https://www.adb.org/projects/37909-024/main | V16: 2009-03-31 | W16: REG: TRADE FINANCE FACILITATION PROGRAM
A17: 16 | B17: AR-016 | C17: A | D17: IFC 'World Region' record of USD 500m or more | E17: IFC | F17: Global Trade Liquidity Program | G17: Regional — Global | H17: 2009 | I17: 1000000000 | J17: USD | K17: 1000 | L17: 4 | M17: IFC's trade programmes stamp their whole envelope on partner records. Since 24 Sep 2026 the loader blanks it wherever several World Region records share one (GSCF, GTSF), but a LONE World Region record keeps its amount as the programme's own. Check whether this is the programme itself or one partner bank. | N17: =HYPERLINK("https://disclosures.ifc.org/project-detail/SPI/28088/global-trade-liquidity-program","Open page") | U17: https://disclosures.ifc.org/project-detail/SPI/28088/global-trade-liquidity-program | V17: 2009-03-31 | W17: Global Trade Liquidity Program
A18: 17 | B18: AR-017 | C18: A | D18: trade-finance line; IFC 'World Region' record of USD 500m or more | E18: IFC | F18: TECF Citi | G18: Regional — Global | H18: 2024 | I18: 1000000000 | J18: USD | K18: 1000 | L18: 5 | M18: IFC's trade programmes stamp their whole envelope on partner records. Since 24 Sep 2026 the loader blanks it wherever several World Region records share one (GSCF, GTSF), but a LONE World Region record keeps its amount as the programme's own. Check whether this is the programme itself or one partner bank. Trade lines revolve: check whether the figure is a LIMIT (one commitment) or a running total of trade covered over the years. | N18: =HYPERLINK("https://disclosures.ifc.org/project-detail/SII/49729/tecf-citi","Open page") | U18: https://disclosures.ifc.org/project-detail/SII/49729/tecf-citi | V18: 2024-11-11 | W18: TECF Citi
A19: 18 | B19: AR-018 | C19: A | D19: trade-finance line | E19: EBRD | F19: Regional TFP: ABC Factors | G19: Greece | H19: 2020 | I19: 860000000 | J19: EUR | K19: 982.28856 | L19: 11 | M19: Trade lines revolve: check whether the figure is a LIMIT (one commitment) or a running total of trade covered over the years. Our figure is EBRD's 'Net Cumulative Bank Investment'. | N19: =HYPERLINK("https://www.google.com/search?q=site%3Aebrd.com%2Fhome%2Fwork-with-us%2Fprojects%2Fpsd+Regional+TFP%3A+ABC+Factors","Search EBRD") | U19: https://www.ebrd.com/content/dam/ebrd_dxp/assets/pdfs/publications/ebrd-investments-1991-2025.xlsx | V19: 2020-11-30 | W19: Regional TFP: ABC Factors
A20: 19 | B20: AR-019 | C20: A | D20: trade-finance line | E20: EBRD | F20: Regional TFP: Alternatifbank | G20: Türkiye | H20: 2016 | I20: 8.6044808e+08 | J20: EUR | K20: 952.43257 | L20: 12 | M20: Trade lines revolve: check whether the figure is a LIMIT (one commitment) or a running total of trade covered over the years. Our figure is EBRD's 'Net Cumulative Bank Investment'. | N20: =HYPERLINK("https://www.google.com/search?q=site%3Aebrd.com%2Fhome%2Fwork-with-us%2Fprojects%2Fpsd+Regional+TFP%3A+Alternatifbank","Search EBRD") | U20: https://www.ebrd.com/content/dam/ebrd_dxp/assets/pdfs/publications/ebrd-investments-1991-2025.xlsx | V20: 2016-12-01 | W20: Regional TFP: Alternatifbank
A21: 20 | B21: AR-020 | C21: A | D21: trade-finance line | E21: EBRD | F21: Regional TFP: Bank of Georgia (Guarantee & Pre-export) | G21: Georgia | H21: 1999 | I21: 8.1880591e+08 | J21: EUR | K21: 872.66369 | L21: 13 | M21: Trade lines revolve: check whether the figure is a LIMIT (one commitment) or a running total of trade covered over the years. Our figure is EBRD's 'Net Cumulative Bank Investment'. | N21: =HYPERLINK("https://www.google.com/search?q=site%3Aebrd.com%2Fhome%2Fwork-with-us%2Fprojects%2Fpsd+Regional+TFP%3A+Bank+of+Georgia+%28Guarantee+%26+Pre-export%29","Search EBRD") | U21: https://www.ebrd.com/content/dam/ebrd_dxp/assets/pdfs/publications/ebrd-investments-1991-2025.xlsx | V21: 1999-07-29 | W21: Regional TFP: Bank of Georgia (Guarantee & Pre-export)
A22: 21 | B22: AR-021 | C22: A | D22: trade-finance line | E22: EBRD | F22: Regional TFP: Vakiflar Bankasi TAO | G22: Türkiye | H22: 2011 | I22: 6.1049468e+08 | J22: EUR | K22: 849.78112 | L22: 14 | M22: Trade lines revolve: check whether the figure is a LIMIT (one commitment) or a running total of trade covered over the years. Our figure is EBRD's 'Net Cumulative Bank Investment'. | N22: =HYPERLINK("https://www.google.com/search?q=site%3Aebrd.com%2Fhome%2Fwork-with-us%2Fprojects%2Fpsd+Regional+TFP%3A+Vakiflar+Bankasi+TAO","Search EBRD") | U22: https://www.ebrd.com/content/dam/ebrd_dxp/assets/pdfs/publications/ebrd-investments-1991-2025.xlsx | V22: 2011-01-26 | W22: Regional TFP: Vakiflar Bankasi TAO
A23: 22 | B23: AR-022 | C23: A | D23: trade-finance line | E23: IDB Invest | F23: Banco Industrial - TFFP | G23: Guatemala | H23: 2008 | I23: 848544000 | J23: USD | K23: 848.544 | L23: 2 | M23: Trade lines revolve: check whether the figure is a LIMIT (one commitment) or a running total of trade covered over the years. | N23: =HYPERLINK("https://idbinvest.org/en/projects/banco-industrial-tffp","Open page") | U23: https://idbinvest.org/en/projects/banco-industrial-tffp | V23: 2008-07-28 | W23: Banco Industrial - TFFP
A24: 23 | B24: AR-023 | C24: A | D24: trade-finance line | E24: EBRD | F24: Regional TFP: Alpha Bank | G24: Greece | H24: 2016 | I24: 7.5374195e+08 | J24: EUR | K24: 834.31923 | L24: 15 | M24: Trade lines revolve: check whether the figure is a LIMIT (one commitment) or a running total of trade covered over the years. Our figure is EBRD's 'Net Cumulative Bank Investment'. | N24: =HYPERLINK("https://www.google.com/search?q=site%3Aebrd.com%2Fhome%2Fwork-with-us%2Fprojects%2Fpsd+Regional+TFP%3A+Alpha+Bank","Search EBRD") | U24: https://www.ebrd.com/content/dam/ebrd_dxp/assets/pdfs/publications/ebrd-investments-1991-2025.xlsx | V24: 2016-07-22 | W24: Regional TFP: Alpha Bank
A25: 24 | B25: AR-024 | C25: A | D25: trade-finance line; IFC 'World Region' record of USD 500m or more | E25: IFC | F25: GTLP CITI VI | G25: Regional — Global | H25: 2024 | I25: 800000000 | J25: USD | K25: 800 | L25: 6 | M25: IFC's trade programmes stamp their whole envelope on partner records. Since 24 Sep 2026 the loader blanks it wherever several World Region records share one (GSCF, GTSF), but a LONE World Region record keeps its amount as the programme's own. Check whether this is the programme itself or one partner bank. Trade lines revolve: check whether the figure is a LIMIT (one commitment) or a running total of trade covered over the years. | N25: =HYPERLINK("https://disclosures.ifc.org/project-detail/SII/49391/gtlp-citi-vi","Open page") | U25: https://disclosures.ifc.org/project-detail/SII/49391/gtlp-citi-vi | V25: 2024-07-16 | W25: GTLP CITI VI
A26: 25 | B26: AR-025 | C26: A | D26: trade-finance line | E26: IDB Invest | F26: Banco Santander Brasil S.A. - TFFP | G26: Brazil | H26: 2013 | I26: 777842000 | J26: USD | K26: 777.842 | L26: 3 | M26: Trade lines revolve: check whether the figure is a LIMIT (one commitment) or a running total of trade covered over the years. | N26: =HYPERLINK("https://idbinvest.org/en/projects/banco-santander-brasil-sa-tffp","Open page") | U26: https://idbinvest.org/en/projects/banco-santander-brasil-sa-tffp | V26: 2013-11-25 | W26: Banco Santander Brasil S.A. - TFFP
A27: 26 | B27: AR-026 | C27: A | D27: trade-finance line | E27: EBRD | F27: Regional TFP: Banque de Tunisie | G27: Tunisia | H27: 2018 | I27: 6.3417372e+08 | J27: EUR | K27: 748.93062 | L27: 18 | M27: Trade lines revolve: check whether the figure is a LIMIT (one commitment) or a running total of trade covered over the years. Our figure is EBRD's 'Net Cumulative Bank Investment'. | N27: =HYPERLINK("https://www.google.com/search?q=site%3Aebrd.com%2Fhome%2Fwork-with-us%2Fprojects%2Fpsd+Regional+TFP%3A+Banque+de+Tunisie","Search EBRD") | U27: https://www.ebrd.com/content/dam/ebrd_dxp/assets/pdfs/publications/ebrd-investments-1991-2025.xlsx | V27: 2018-06-11 | W27: Regional TFP: Banque de Tunisie
A28: 27 | B28: AR-027 | C28: A | D28: trade-finance line | E28: EBRD | F28: Regional TFP: QNB Finansbank | G28: Türkiye | H28: 2020 | I28: 6.5101141e+08 | J28: EUR | K28: 743.58263 | L28: 19 | M28: Trade lines revolve: check whether the figure is a LIMIT (one commitment) or a running total of trade covered over the years. Our figure is EBRD's 'Net Cumulative Bank Investment'. | N28: =HYPERLINK("https://www.google.com/search?q=site%3Aebrd.com%2Fhome%2Fwork-with-us%2Fprojects%2Fpsd+Regional+TFP%3A+QNB+Finansbank","Search EBRD") | U28: https://www.ebrd.com/content/dam/ebrd_dxp/assets/pdfs/publications/ebrd-investments-1991-2025.xlsx | V28: 2020-06-11 | W28: Regional TFP: QNB Finansbank
A29: 28 | B29: AR-028 | C29: A | D29: trade-finance line | E29: IDB Invest | F29: Banco ABC Brasil S.A. - TFFP Line | G29: Brazil | H29: 2020 | I29: 741018000 | J29: USD | K29: 741.018 | L29: 4 | M29: Trade lines revolve: check whether the figure is a LIMIT (one commitment) or a running total of trade covered over the years. | N29: =HYPERLINK("https://idbinvest.org/en/projects/banco-abc-brasil-sa-tffp-line","Open page") | U29: https://idbinvest.org/en/projects/banco-abc-brasil-sa-tffp-line | V29: 2020-05-29 | W29: Banco ABC Brasil S.A. - TFFP Line
A30: 29 | B30: AR-029 | C30: A | D30: trade-finance line | E30: EBRD | F30: Regional TFP: Piraeus Bank S.A. | G30: Greece | H30: 2016 | I30: 5.9758718e+08 | J30: EUR | K30: 661.47104 | L30: 20 | M30: Trade lines revolve: check whether the figure is a LIMIT (one commitment) or a running total of trade covered over the years. Our figure is EBRD's 'Net Cumulative Bank Investment'. | N30: =HYPERLINK("https://www.google.com/search?q=site%3Aebrd.com%2Fhome%2Fwork-with-us%2Fprojects%2Fpsd+Regional+TFP%3A+Piraeus+Bank+S.A.","Search EBRD") | U30: https://www.ebrd.com/content/dam/ebrd_dxp/assets/pdfs/publications/ebrd-investments-1991-2025.xlsx | V30: 2016-10-03 | W30: Regional TFP: Piraeus Bank S.A.
A31: 30 | B31: AR-030 | C31: A | D31: trade-finance line; IFC 'World Region' record of USD 500m or more | E31: IFC | F31: GTFP- IDA PSW | G31: Regional — Global | H31: 2020 | I31: 650000000 | J31: USD | K31: 650 | L31: 7 | M31: IFC's trade programmes stamp their whole envelope on partner records. Since 24 Sep 2026 the loader blanks it wherever several World Region records share one (GSCF, GTSF), but a LONE World Region record keeps its amount as the programme's own. Check whether this is the programme itself or one partner bank. Trade lines revolve: check whether the figure is a LIMIT (one commitment) or a running total of trade covered over the years. | N31: =HYPERLINK("https://disclosures.ifc.org/project-detail/SII/44011/gtfp--ida-psw","Open page") | U31: https://disclosures.ifc.org/project-detail/SII/44011/gtfp--ida-psw | V31: 2020-04-24 | W31: GTFP- IDA PSW
A32: 31 | B32: AR-031 | C32: A | D32: trade-finance line | E32: EBRD | F32: Regional TFP: UzPSB | G32: Uzbekistan | H32: 2019 | I32: 5.7049262e+08 | J32: EUR | K32: 638.65223 | L32: 21 | M32: Trade lines revolve: check whether the figure is a LIMIT (one commitment) or a running total of trade covered over the years. Our figure is EBRD's 'Net Cumulative Bank Investment'. | N32: =HYPERLINK("https://www.google.com/search?q=site%3Aebrd.com%2Fhome%2Fwork-with-us%2Fprojects%2Fpsd+Regional+TFP%3A+UzPSB","Search EBRD") | U32: https://www.ebrd.com/content/dam/ebrd_dxp/assets/pdfs/publications/ebrd-investments-1991-2025.xlsx | V32: 2019-03-21 | W32: Regional TFP: UzPSB
A33: 32 | B33: AR-032 | C33: A | D33: trade-finance line | E33: EBRD | F33: Regional TFP: JSCB OTP Bank, Ukraine | G33: Ukraine | H33: 2002 | I33: 6.5934429e+08 | J33: EUR | K33: 623.45882 | L33: 22 | M33: Trade lines revolve: check whether the figure is a LIMIT (one commitment) or a running total of trade covered over the years. Our figure is EBRD's 'Net Cumulative Bank Investment'. | N33: =HYPERLINK("https://www.google.com/search?q=site%3Aebrd.com%2Fhome%2Fwork-with-us%2Fprojects%2Fpsd+Regional+TFP%3A+JSCB+OTP+Bank%2C+Ukraine","Search EBRD") | U33: https://www.ebrd.com/content/dam/ebrd_dxp/assets/pdfs/publications/ebrd-investments-1991-2025.xlsx | V33: 2002-10-22 | W33: Regional TFP: JSCB OTP Bank, Ukraine
A34: 33 | B34: AR-033 | C34: A | D34: trade-finance line; IFC 'World Region' record of USD 500m or more | E34: IFC | F34: GTLP Citi III | G34: Regional — Global | H34: 2015 | I34: 600000000 | J34: USD | K34: 600 | L34: 8 | M34: IFC's trade programmes stamp their whole envelope on partner records. Since 24 Sep 2026 the loader blanks it wherever several World Region records share one (GSCF, GTSF), but a LONE World Region record keeps its amount as the programme's own. Check whether this is the programme itself or one partner bank. Trade lines revolve: check whether the figure is a LIMIT (one commitment) or a running total of trade covered over the years. | N34: =HYPERLINK("https://disclosures.ifc.org/project-detail/SII/36386/gtlp-citi-iii","Open page") | U34: https://disclosures.ifc.org/project-detail/SII/36386/gtlp-citi-iii | V34: 2015-05-15 | W34: GTLP Citi III
A35: 34 | B35: AR-034 | C35: A | D35: trade-finance line; IFC 'World Region' record of USD 500m or more | E35: IFC | F35: GTLP Citi IV | G35: Regional — Global | H35: 2018 | I35: 600000000 | J35: USD | K35: 600 | L35: 9 | M35: IFC's trade programmes stamp their whole envelope on partner records. Since 24 Sep 2026 the loader blanks it wherever several World Region records share one (GSCF, GTSF), but a LONE World Region record keeps its amount as the programme's own. Check whether this is the programme itself or one partner bank. Trade lines revolve: check whether the figure is a LIMIT (one commitment) or a running total of trade covered over the years. | N35: =HYPERLINK("https://disclosures.ifc.org/project-detail/SII/40688/gtlp-citi-iv","Open page") | U35: https://disclosures.ifc.org/project-detail/SII/40688/gtlp-citi-iv | V35: 2018-05-31 | W35: GTLP Citi IV
A36: 35 | B36: AR-035 | C36: A | D36: trade-finance line; IFC 'World Region' record of USD 500m or more | E36: IFC | F36: GTLP CITI V | G36: Regional — Global | I36: 600000000 | J36: USD | K36: 600 | L36: 10 | M36: IFC's trade programmes stamp their whole envelope on partner records. Since 24 Sep 2026 the loader blanks it wherever several World Region records share one (GSCF, GTSF), but a LONE World Region record keeps its amount as the programme's own. Check whether this is the programme itself or one partner bank. Trade lines revolve: check whether the figure is a LIMIT (one commitment) or a running total of trade covered over the years. | N36: =HYPERLINK("https://disclosures.ifc.org/project-detail/SII/45495/gtlp-citi-v","Open page") | U36: https://disclosures.ifc.org/project-detail/SII/45495/gtlp-citi-v | W36: GTLP CITI V
A37: 36 | B37: AR-036 | C37: A | D37: trade-finance line | E37: EBRD | F37: Regional TFP: Vneshtorgbank (Guarantee & Pre-export) | G37: Russia | H37: 1999 | I37: 5.4885691e+08 | J37: EUR | K37: 584.95852 | L37: 24 | M37: Trade lines revolve: check whether the figure is a LIMIT (one commitment) or a running total of trade covered over the years. Our figure is EBRD's 'Net Cumulative Bank Investment'. | N37: =HYPERLINK("https://www.google.com/search?q=site%3Aebrd.com%2Fhome%2Fwork-with-us%2Fprojects%2Fpsd+Regional+TFP%3A+Vneshtorgbank+%28Guarantee+%26+Pre-export%29","Search EBRD") | U37: https://www.ebrd.com/content/dam/ebrd_dxp/assets/pdfs/publications/ebrd-investments-1991-2025.xlsx | V37: 1999-06-10 | W37: Regional TFP: Vneshtorgbank (Guarantee & Pre-export)
A38: 37 | B38: AR-037 | C38: A | D38: trade-finance line | E38: EBRD | F38: Regional TFP: Burgan Bank AS | G38: Türkiye | H38: 2017 | I38: 5.0401326e+08 | J38: EUR | K38: 569.37421 | L38: 25 | M38: Trade lines revolve: check whether the figure is a LIMIT (one commitment) or a running total of trade covered over the years. Our figure is EBRD's 'Net Cumulative Bank Investment'. | N38: =HYPERLINK("https://www.google.com/search?q=site%3Aebrd.com%2Fhome%2Fwork-with-us%2Fprojects%2Fpsd+Regional+TFP%3A+Burgan+Bank+AS","Search EBRD") | U38: https://www.ebrd.com/content/dam/ebrd_dxp/assets/pdfs/publications/ebrd-investments-1991-2025.xlsx | V38: 2017-02-09 | W38: Regional TFP: Burgan Bank AS
A39: 38 | B39: AR-038 | C39: A | D39: trade-finance line | E39: EBRD | F39: Regional TFP: Ameria Bank CJSC | G39: Armenia | H39: 2010 | I39: 4.0013057e+08 | J39: EUR | K39: 530.45989 | L39: 29 | M39: Trade lines revolve: check whether the figure is a LIMIT (one commitment) or a running total of trade covered over the years. Our figure is EBRD's 'Net Cumulative Bank Investment'. | N39: =HYPERLINK("https://www.google.com/search?q=site%3Aebrd.com%2Fhome%2Fwork-with-us%2Fprojects%2Fpsd+Regional+TFP%3A+Ameria+Bank+CJSC","Search EBRD") | U39: https://www.ebrd.com/content/dam/ebrd_dxp/assets/pdfs/publications/ebrd-investments-1991-2025.xlsx | V39: 2010-05-15 | W39: Regional TFP: Ameria Bank CJSC
A40: 39 | B40: AR-039 | C40: A | D40: trade-finance line | E40: EBRD | F40: Regional TFP : Bank al Etihad | G40: Jordan | H40: 2014 | I40: 3.9439071e+08 | J40: EUR | K40: 523.94846 | L40: 30 | M40: Trade lines revolve: check whether the figure is a LIMIT (one commitment) or a running total of trade covered over the years. Our figure is EBRD's 'Net Cumulative Bank Investment'. | N40: =HYPERLINK("https://www.google.com/search?q=site%3Aebrd.com%2Fhome%2Fwork-with-us%2Fprojects%2Fpsd+Regional+TFP+%3A+Bank+al+Etihad","Search EBRD") | U40: https://www.ebrd.com/content/dam/ebrd_dxp/assets/pdfs/publications/ebrd-investments-1991-2025.xlsx | V40: 2014-12-18 | W40: Regional TFP : Bank al Etihad
...

Sheet Institution guide
A1: Institution | B1: Where the amount is | C1: Differences that are NORMAL here | D1: Page layout checked 24 Sep 2026?
A2: IFC | B2: Open the link. Click the section 'Total Project Cost and Amount and Nature of IFC's Investment'. It gives the total project and IFC's own investment separately; compare OUR amount with IFC's investment. | C2: Loan plus equity may be listed separately; add them. 'Up to' figures are fine. | D2: Yes
A3: EBRD | B3: There is no page per record: the link is a web search. Open the result whose address contains '/projects/psd/'. That is the Project Summary Document; its financing section states EBRD's own amount. | C3: Our figure is EBRD's 'Net Cumulative Bank Investment' from its portfolio list, not the signing amount, so it can differ from the PSD. A much LARGER figure than the PSD is exactly what to look for. | D3: Search only; PSD layout not checked
A4: EIB Global | B4: Open the link and click 'Signature(s)'. It lists the signed amount and each signature date. | C4: EIB publishes loan tranches, so one project can be several of our records. Match OUR amount to one signature line, not the project total. | D4: Yes
A5: AfDB | B5: Open the link and read 'Commitment (UA)' on Overview. Then click 'Financial information': under 'Commitments by source' note the African Development Bank Group line. | C5: Amounts are in UA (Units of Account, the IMF's SDR). Record UA figures, not USD. If 'Commitments by source' shows other financiers, OUR figure may include them — say so in Notes. | D5: Yes
A6: IDB Invest | B6: Open the link. 'Investment summary' shows 'FINANCING AMOUNT'. | C6: The page can show the whole IDB Group's figure, typically 1.8 to 5.3 times IDB Invest's own share, which is what we load. A LARGER page figure is expected; a SMALLER one is a problem. | D6: Yes
A7: FMO | B7: Open the link. Read 'Total FMO financing' in the side panel. | C7: 'Funding' says whose money it was: 'FMO NV' is FMO's own account; anything else is a government fund FMO manages. | D7: Yes
A8: DFC | B8: The link is a PDF project summary. Look for the proposed DFC financing amount. | C8: Records named 'Redacted' have no public page: mark 'Can't verify'. | D8: No
A9: ADB | B9: Open the link (your browser may show a security check first). Look for the financing table, ADB's own line. | C9: One ADB record is in Indian rupees; its description says 'up to $750 million'. | D9: No - the site blocked automated checking
A10: BII | B10: The link opens d-portal (the IATI data viewer). Look at the commitment transactions for this activity. | C10: BII publishes transactions, so one deal can be several records. | D10: No
A11: Proparco | B11: Open the link (French). Look for 'Montant' / the amount of Proparco's financing. Records loaded from AFD's open data have no page of their own: the link is a web search instead. | C11: Amounts are in EUR. | D11: No

Sheet Progress
A1: Progress
B3: All | C3: A | D3: B | E3: C
A4: Records in the queue | B4: =COUNTA(Queue!$B$2:$B$214) | C4: =COUNTIF(Queue!$C$2:$C$214,"A") | D4: =COUNTIF(Queue!$C$2:$C$214,"B") | E4: =COUNTIF(Queue!$C$2:$C$214,"C")
A5: Reviewed (any verdict) | B5: =COUNTA(Queue!$O$2:$O$214) | C5: =COUNTIFS(Queue!$C$2:$C$214,"A",Queue!$O$2:$O$214,"<>") | D5: =COUNTIFS(Queue!$C$2:$C$214,"B",Queue!$O$2:$O$214,"<>") | E5: =COUNTIFS(Queue!$C$2:$C$214,"C",Queue!$O$2:$O$214,"<>")
A6: Correct - matches the page | B6: =COUNTIF(Queue!$O$2:$O$214,$A6) | C6: =COUNTIFS(Queue!$C$2:$C$214,"A",Queue!$O$2:$O$214,$A6) | D6: =COUNTIFS(Queue!$C$2:$C$214,"B",Queue!$O$2:$O$214,$A6) | E6: =COUNTIFS(Queue!$C$2:$C$214,"C",Queue!$O$2:$O$214,$A6)
A7: Correct - small difference (rounding or exchange rate) | B7: =COUNTIF(Queue!$O$2:$O$214,$A7) | C7: =COUNTIFS(Queue!$C$2:$C$214,"A",Queue!$O$2:$O$214,$A7) | D7: =COUNTIFS(Queue!$C$2:$C$214,"B",Queue!$O$2:$O$214,$A7) | E7: =COUNTIFS(Queue!$C$2:$C$214,"C",Queue!$O$2:$O$214,$A7)
A8: Wrong - programme or envelope total, not this deal | B8: =COUNTIF(Queue!$O$2:$O$214,$A8) | C8: =COUNTIFS(Queue!$C$2:$C$214,"A",Queue!$O$2:$O$214,$A8) | D8: =COUNTIFS(Queue!$C$2:$C$214,"B",Queue!$O$2:$O$214,$A8) | E8: =COUNTIFS(Queue!$C$2:$C$214,"C",Queue!$O$2:$O$214,$A8)
A9: Wrong - total project cost, not this institution's share | B9: =COUNTIF(Queue!$O$2:$O$214,$A9) | C9: =COUNTIFS(Queue!$C$2:$C$214,"A",Queue!$O$2:$O$214,$A9) | D9: =COUNTIFS(Queue!$C$2:$C$214,"B",Queue!$O$2:$O$214,$A9) | E9: =COUNTIFS(Queue!$C$2:$C$214,"C",Queue!$O$2:$O$214,$A9)
A10: Wrong - cumulative or revolving total, not one commitment | B10: =COUNTIF(Queue!$O$2:$O$214,$A10) | C10: =COUNTIFS(Queue!$C$2:$C$214,"A",Queue!$O$2:$O$214,$A10) | D10: =COUNTIFS(Queue!$C$2:$C$214,"B",Queue!$O$2:$O$214,$A10) | E10: =COUNTIFS(Queue!$C$2:$C$214,"C",Queue!$O$2:$O$214,$A10)
A11: Wrong - currency or units | B11: =COUNTIF(Queue!$O$2:$O$214,$A11) | C11: =COUNTIFS(Queue!$C$2:$C$214,"A",Queue!$O$2:$O$214,$A11) | D11: =COUNTIFS(Queue!$C$2:$C$214,"B",Queue!$O$2:$O$214,$A11) | E11: =COUNTIFS(Queue!$C$2:$C$214,"C",Queue!$O$2:$O$214,$A11)
A12: Wrong - other (explain in Notes) | B12: =COUNTIF(Queue!$O$2:$O$214,$A12) | C12: =COUNTIFS(Queue!$C$2:$C$214,"A",Queue!$O$2:$O$214,$A12) | D12: =COUNTIFS(Queue!$C$2:$C$214,"B",Queue!$O$2:$O$214,$A12) | E12: =COUNTIFS(Queue!$C$2:$C$214,"C",Queue!$O$2:$O$214,$A12)
A13: Can't verify - no link, page gone, or no amount shown | B13: =COUNTIF(Queue!$O$2:$O$214,$A13) | C13: =COUNTIFS(Queue!$C$2:$C$214,"A",Queue!$O$2:$O$214,$A13) | D13: =COUNTIFS(Queue!$C$2:$C$214,"B",Queue!$O$2:$O$214,$A13) | E13: =COUNTIFS(Queue!$C$2:$C$214,"C",Queue!$O$2:$O$214,$A13)
A14: Unsure - discuss | B14: =COUNTIF(Queue!$O$2:$O$214,$A14) | C14: =COUNTIFS(Queue!$C$2:$C$214,"A",Queue!$O$2:$O$214,$A14) | D14: =COUNTIFS(Queue!$C$2:$C$214,"B",Queue!$O$2:$O$214,$A14) | E14: =COUNTIFS(Queue!$C$2:$C$214,"C",Queue!$O$2:$O$214,$A14)
A15: Still to do | B15: =B4-B5 | C15: =C4-C5 | D15: =D4-D5 | E15: =E4-E5
A17: Counts update as you fill the Verdict column. 'Reviewed' counts any row with a verdict.

Sheet Lists
A1: Correct - matches the page
A2: Correct - small difference (rounding or exchange rate)
A3: Wrong - programme or envelope total, not this deal
A4: Wrong - total project cost, not this institution's share
A5: Wrong - cumulative or revolving total, not one commitment
A6: Wrong - currency or units
A7: Wrong - other (explain in Notes)
A8: Can't verify - no link, page gone, or no amount shown
A9: Unsure - discuss
